Workbook
Name solver_opt: 'Part A'!$BV$28
Name solver_lhs1: 'Part A'!$BV$24
Name solver_adj: 'Part A'!$BR$24:$BU$24

Sheet Introduction
B2: 🔍SAPM Assignment - Summer Term 2025🪴
B11: Team | F11: Index
B12: Name | C12: ID Number
F13: Approach Summary | G13: Individual Stock Selection > Our Approach > Selection of Industry > Selection of a stock in a particular industry
B14: Arnav Agarwal | C14: 2022B1A41724P
B15: Atharva Toshniwal | C15: 2022B3A80224P
F16: Part A | G16: > Performance of the selected stocks in one year ( from April 2024 to April 2025) > Equal Weighted Performance > Optimized Portfolio Performance
F19: Part B | G19: > Backtesting of the selected stocks in one month ( May 2025)
F22: Part C | G22: > Performance of the selected instruments in one year ( from April 2024 to April 2025) > Equal Weighted Performance > Optimized Portfolio Performance
F25: Part D | G25: > Backtesting of the selected instruments in one month ( May 2025)
F28: Part E | G28: > Observations > Final Conclusions

Sheet Approach Summary
B3: 🎯 Our Approach 📃
B4: Step 1 | C4: We began by identifying key industries based on their economic importance, market stability, and historical return potential. Preference was given to sectors demonstrating strong growth prospects and consistent performance.
B5: Step 2 | C5: For each selected industry, we shortlisted five leading companies. These were chosen based on market capitalization, brand strength, historical returns, and relevance within the sector.
B6: Step 3 | C6: The evaluation criteria were grouped into five core categories: valuation metrics, profitability metrics, efficiency metrics, leverage/liquidity metrics, and market strength/scale metrics.
B7: Step 4 | C7: Each metric and sub-metric was assigned a specific weight based on its relevance to the industry context. The weights were supported by rationale rooted in financial theory and sector characteristics.
B8: Step 5 | C8: To ensure comparability across different scales and units, all metric values were normalized. For positively contributing metrics (e.g., ROE, Net Profit Margin, Asset Turnover ⬆️), we applied: Normalized Value= (Value−Min) / (Max−Min)
B9: Step 6 | C9: For negatively contributing metrics (e.g., P/E Ratio, Debt-to-Equity, Inventory Days ⬇️), we used: Normalized Value = (Max − Value) / (Max − Min)
B10: Step 7 | C10: Normalized values were then multiplied by their respective metric weights to compute a final weighted score for each stock.
B11: Step 8 | C11: The company with the highest cumulative weighted score in each industry was selected, reflecting optimal performance across valuation, operational, and financial parameters.
B14: Why Tele - Communications? | C14: The telecom industry plays a critical role in enabling digital infrastructure and connectivity in India, making it foundational to both economic activity and national development. With the rapid expansion of 5G, increased data consumption, and digital payments, telecom companies are set to benefit from long-term demand. Additionally, the sector features strong industry leaders with wide subscriber bases, high entry barriers, and consistent cash flows. These attributes make it attractive for stable, long-term portfolio inclusion.
B17: 📡Stocks of Tele-Communications📞
D21: Valuation💰 | O21: Profitability 💸 | X21: Efficiency 🔁 | AC21: Financial Health 🩺 | AJ21: Returns 📈 | AO21: Final Value
B22: Name of the ratio | D22: P/E Ratio | F22: P/B Ratio | H22: EV/EBITDA | J22: PEG Ratio | L22: Market Cap (in Cr) | O22: Net Profit Margin | Q22: ROE | S22: ROA | U22: Gross Margin | X22: Asset Turnover | Z22: Inventory Turnover | AC22: Current Ratio | AE22: Debt-to-Equity | AG22: Interest Coverage | AJ22: Operating Margin | AL22: Dividend Yield
B23: Weight | D23: 0.08 | F23: 0.05 | H23: 0.1 | J23: 0.05 | L23: 0.02 | O23: 0.07 | Q23: 0.1 | S23: 0.05 | U23: 0.03 | X23: 0.07 | Z23: 0.08 | AC23: 0.07 | AE23: 0.1 | AG23: 0.03 | AJ23: 0.05 | AL23: 0.05
B24: Reason | D24: Telecoms are mature and earnings-stable; P/E captures valuation based on profitability and investor sentiment. | F24: Book value is less indicative in telecoms due to high asset depreciation and long-lived infrastructure. | H24: The most accurate metric for telecoms, accounting for debt and depreciation in this high-capex industry. | J24: Telecoms have stable, moderate growth; this ratio adds context to valuation by factoring in expected growth. | L24: While scale offers network advantages, telecom markets are often regulated, so size doesn’t always mean dominance. | O24: Margins matter due to high operating leverage; small margin shifts can significantly impact profits. | Q24: Crucial for capital-heavy firms, shows how well telecoms convert invested capital into profit. | S24: Telecoms have large fixed asset bases; ROA shows how productively these are deployed, but leverage skews it. | U24: Fixed infrastructure costs dominate telecoms, so gross margin varies little and has limited insight. | X24: Telecoms must monetize infrastructure efficiently; asset turnover captures how well they do it. | Z24: Many telecoms sell devices or maintain inventory; turnover reflects working capital and sales flow health. | AC24: Telecoms face high liabilities; current ratio reveals ability to meet obligations. | AE24: Telecoms are often heavily leveraged due to infrastructure investment, managing debt load is critical. | AG24: Important in debt-heavy sectors, but often less volatile in large telecoms with steady cash flows. | AJ24: Reflects efficiency in core services, but overlaps with EBITDA, so slightly lower weight. | AL24: Many telecoms are mature and offer dividends, but capital reinvestment can be more important for growth.
D25: Lower⬇️ | E25: Value Weighted | F25: Lower⬇️ | G25: Value Weighted | H25: Lower⬇️ | I25: Value Weighted | J25: Lower⬇️ | K25: Value Weighted | L25: Higher⬆️ | M25: Value Weighted | O25: Higher⬆️ | P25: Value Weighted | Q25: Higher⬆️ | R25: Value Weighted | S25: Higher⬆️ | T25: Value Weighted | U25: Higher⬆️ | V25: Value Weighted | X25: Higher⬆️ | Y25: Value Weighted | Z25: Higher⬆️ | AA25: Value Weighted | AC25: Higher⬆️ | AD25: Value Weighted | AE25: Lower⬇️ | AF25: Value Weighted | AG25: Higher⬆️ | AH25: Value Weighted | AJ25: Higher⬆️ | AK25: Value Weighted | AL25: Higher⬆️ | AM25: Value Weighted
B26: Bharti Airtel Ltd | D26: 43.9 | E26: 0.47 | F26: 10.2 | G26: 0.48 | H26: 14.4 | I26: 0.54 | J26: 1.43 | K26: 0.66 | L26: 1216200 | M26: 1 | O26: 0.26 | P26: 1 | Q26: 0.28 | R26: 0.3 | S26: 0.06 | T26: 0.11 | U26: 1 | V26: 1 | X26: 0.36 | Y26: 0 | Z26: NA | AA26: 0 | AC26: 0.37 | AD26: 0.09 | AE26: 1.88 | AF26: 0.46 | AG26: 2.43 | AH26: 0 | AJ26: 0.54 | AK26: 0.71 | AL26: 0.0079 | AM26: 0.53 | AO26: 0.41861711
B28: Indus Towers Ltd | D28: 11.2 | E28: 1 | F28: 3.42 | G28: 1 | H28: 6.15 | I28: 1 | J28: 0.42 | K28: 1 | L28: 111085 | M28: 0.08 | O28: 0.23 | P28: 0.85 | Q28: 0.33 | R28: 0.44 | S28: 0.17 | T28: 1 | U28: 0.63 | V28: 0 | X28: 0.51 | Y28: 0.27 | Z28: 3012.84 | AA28: 0 | AC28: 1.32 | AD28: 1 | AE28: 0.65 | AF28: 0.15 | AG28: 9.05 | AH28: 0.05 | AJ28: 0.69 | AK28: 1 | AL28: 0 | AM28: 0 | AO28: 0.5905296
B30: Bharti Hexacom Ltd | D30: 73.1 | E30: 0 | F30: 16.5 | G30: 0 | H30: 24 | I30: 0 | J30: 2.07 | K30: 0.45 | L30: 98005 | M30: 0.07 | O30: 0.21 | P30: 0.73 | Q30: 0.25 | R30: 0.23 | S30: 0.07 | T30: 0.16 | U30: 1 | V30: 1 | X30: 0.45 | Y30: 0.16 | Z30: NA | AA30: 0 | AC30: 0.28 | AD30: 0 | AE30: 1.24 | AF30: 0.3 | AG30: 3.32 | AH30: 0.01 | AJ30: 0.49 | AK30: 0.63 | AL30: 0.0051 | AM30: 0.34 | AO30: 0.22600959
B32: Tata Communications Ltd | D32: 36.1 | E32: 0.6 | F32: 15.8 | G32: 0.05 | H32: 12.7 | I32: 0.63 | J32: 1.05 | K32: 0.79 | L32: 47846 | M32: 0.03 | O32: 0.05 | P32: 0 | Q32: 0.55 | R32: 1 | S32: 0.05 | T32: 0 | U32: 1 | V32: 1 | X32: 0.91 | Y32: 1 | Z32: 3.03 | AA32: 0 | AC32: 0.51 | AD32: 0.22 | AE32: 4.09 | AF32: 1 | AG32: 2.88 | AH32: 0 | AJ32: 0.2 | AK32: 0.08 | AL32: 0.0149 | AM32: 1 | AO32: 0.52355242
B34: Railtel Corporation of India Ltd | D34: 43.6 | E34: 0.48 | F34: 6.87 | G34: 0.74 | H34: 21.8 | I34: 0.12 | J34: 3.4 | K34: 0 | L34: 13746 | M34: 0 | O34: 0.08 | P34: 0.15 | Q34: 0.17 | R34: 0 | S34: 0.07 | T34: 0.14 | U34: 1 | V34: 1 | X34: 0.76 | Y34: 0.73 | Z34: NA | AA34: 0 | AC34: 1.29 | AD34: 0.97 | AE34: 0.02 | AF34: 0 | AG34: 137 | AH34: 1 | AJ34: 0.15 | AK34: 0 | AL34: 0.0067 | AM34: 0.45 | AO34: 0.30607056
B36: Why Defence? | C36: The defence sector in India is gaining prominence due to increasing government focus on indigenization, rising defence budgets, and strategic geopolitical priorities. With large, long-term contracts and government backing, this sector presents a unique blend of stability and long-term growth. Prominent companies benefit from monopolistic or semi-monopolistic market positions and offer significant upside as the sector expands through Make in India initiatives.
B38: 🏰 Stocks of Defence 🪖
D42: Valuation💰 | O42: Profitability 💸 | X42: Efficiency 🔁 | AC42: Financial Health 🩺 | AJ42: Returns 📈 | AO42: Final Value
B43: Name of the ratio | D43: P/E Ratio | F43: P/B Ratio | H43: EV/EBITDA | J43: PEG Ratio | L43: Market Cap | O43: Net Profit Margin | Q43: ROE | S43: ROA | U43: Gross Margin | X43: Asset Turnover | Z43: Inventory Turnover | AC43: Current Ratio | AE43: Debt-to-Equity | AG43: Interest Coverage | AJ43: Operating Margin | AL43: Dividend Yield
B44: Weight | D44: 0.05 | F44: 0.07 | H44: 0.12 | J44: 0.03 | L44: 0.03 | O44: 0.08 | Q44: 0.12 | S44: 0.06 | U44: 0.05 | X44: 0.06 | Z44: 0.05 | AC44: 0.1 | AE44: 0.12 | AG44: 0.05 | AJ44: 0.06 | AL44: 0.04
B45: Reason | D45: Earnings can fluctuate with contracts and defense budgets, so less predictive on its own. | F45: Important for asset-heavy defence manufacturers where tangible assets like plants and IP matter. | H45: Essential for capital-intensive firms; neutralizes accounting and capex differences. | J45: Many defence companies grow steadily but slowly, growth potential is less central than cash flow. | L45: Larger firms win bigger contracts and offer stability, but scale isn’t always correlated with performance. | O45: Important for contract profitability, especially in cost-plus vs. fixed-price models. | Q45: Vital in defence where firms must efficiently use capital while facing long sales cycles. | S45: Useful in assessing how well plants, equipment, and R&D investments are leveraged. | U45: Indicates pricing power and manufacturing cost control, especially in complex production. | X45: Key for companies with high R&D or inventory levels; shows contract-to-revenue speed. | Z45: Defence has long build cycles and specialized parts, so turnover offers limited insight but still relevant. | AC45: Crucial in managing contract milestones, delayed payments, and high working capital needs. | AE45: High weight due to the need for financial stability in a sector with unpredictable payment cycles. | AG45: Important for balance sheet health, though most defense firms are cash-positive. | AJ45: Contract execution efficiency is critical; reflects profitability beyond COGS. | AL45: Defence stocks often attract long-term investors; dividends add income but are secondary to stability.
D46: Lower⬇️ | E46: Value Weighted | F46: Lower⬇️ | G46: Value Weighted | H46: Lower⬇️ | I46: Value Weighted | J46: Lower⬇️ | K46: Value Weighted | L46: Higher⬆️ | M46: Value Weighted | O46: Higher⬆️ | P46: Value Weighted | Q46: Higher⬆️ | R46: Value Weighted | S46: Higher⬆️ | T46: Value Weighted | U46: Higher⬆️ | V46: Value Weighted | X46: Higher⬆️ | Y46: Value Weighted | Z46: Higher⬆️ | AA46: Value Weighted | AC46: Higher⬆️ | AD46: Value Weighted | AE46: Lower⬇️ | AF46: Value Weighted | AG46: Higher⬆️ | AH46: Value Weighted | AJ46: Higher⬆️ | AK46: Value Weighted | AL46: Higher⬆️ | AM46: Value Weighted
B47: Hindustan Aeronautics Ltd | D47: 39.2 | E47: 1 | F47: 9.36 | G47: 1 | H47: 23.7 | I47: 1 | J47: 1.6 | K47: 0.99903348 | L47: 327559 | M47: 1 | O47: 0.29 | P47: 1 | Q47: 0.261 | R47: 0.6 | S47: 0.0893 | T47: 1 | U47: 0.637 | V47: 0.94 | X47: 0.33 | Y47: 0.16 | Z47: 0.65 | AA47: 0 | AC47: 2.04 | AD47: 0.72 | AE47: 0 | AF47: 0 | AG47: 1252 | AH47: 1 | AJ47: 0.31 | AK47: 1 | AL47: 0.0071 | AM47: 1 | AO47: 0.78995702
B49: Mazagon Dock Shipbuilders Ltd | D49: 53 | E49: 0.84 | F49: 16.1 | G49: 0.15 | H49: 35.2 | I49: 0.79 | J49: 1.38 | K49: 1 | L49: 128033 | M49: 0.32 | O49: 0.102 | P49: 0 | Q49: 0.34 | R49: 1 | S49: 0.083 | T49: 0.84 | U49: 0.657 | V49: 1 | X49: 0.39 | Y49: 0.47 | Z49: 0.89 | AA49: 0.3 | AC49: 1.25 | AD49: 0.07 | AE49: 0 | AF49: 0 | AG49: 697 | AH49: 0.55 | AJ49: 0.18 | AK49: 0.43 | AL49: 0.0046 | AM49: 0.42 | AO49: 0.52723966
B51: Bharat Dynamics Ltd | D51: 126 | E51: 0 | F51: 17.3 | G51: 0 | H51: 79.1 | I51: 0 | J51: 229 | K51: 0 | L51: 69284 | M51: 0.12 | O51: 0.154 | P51: 0.28 | Q51: 0.144 | R51: 0 | S51: 0.0496 | T51: 0 | U51: 0.408 | V51: 0.25 | X51: 0.3 | Y51: 0 | Z51: 0.71 | AA51: 0.07 | AC51: 2.38 | AD51: 1 | AE51: 0 | AF51: 0 | AG51: 227 | AH51: 0.16 | AJ51: 0.141 | AK51: 0.26 | AL51: 0.0028 | AM51: 0 | AO51: 0.16507603
B53: Cochin Shipyard Ltd | D53: 63.8 | E53: 0.72 | F53: 9.59 | G53: 0.97 | H53: 40.9 | I53: 0.69 | J53: 11 | K53: 0.95773658 | L53: 53779 | M53: 0.07 | O53: 0.172 | P53: 0.37 | Q53: 0.158 | R53: 0.07 | S53: 0.0676 | T53: 0.45 | U53: 0.606 | V53: 0.85 | X53: 0.36 | Y53: 0.32 | Z53: 1.46 | AA53: 1 | AC53: 1.34 | AD53: 0.14 | AE53: 0.09 | AF53: 1 | AG53: 32.1 | AH53: 0 | AJ53: 0.193 | AK53: 0.48 | AL53: 0.0048 | AM53: 0.47 | AO53: 0.57576351
B55: Garden Reach Shipbuilders & Engineers Ltd | D55: 65.9 | E55: 0.69 | F55: 16.7 | G55: 0.08 | H55: 41 | I55: 0.69 | J55: 2.54 | K55: 0.99490379 | L55: 34739 | M55: 0 | O55: 0.149 | P55: 0.25 | Q55: 0.281 | R55: 0.7 | S55: 0.0512 | T55: 0.04 | U55: 0.326 | V55: 0 | X55: 0.49 | Y55: 1 | Z55: 0.94 | AA55: 0.36 | AC55: 1.17 | AD55: 0 | AE55: 0 | AF55: 0 | AG55: 69.2 | AH55: 0.03 | AJ55: 0.083 | AK55: 0 | AL55: 0.0031 | AM55: 0.07 | AO55: 0.34079191
B57: Why Banks? | C57: The banking sector is a core component of the economy, essential for financial intermediation, credit distribution, and liquidity management. It reflects the broader economic cycle and plays a critical role in supporting growth through retail and corporate lending. We chose this sector due to its strong linkage to GDP expansion, rising credit demand, and rapid digitalization of financial services. Leading banks typically exhibit healthy balance sheets, stable net interest margins, and improving asset quality. The sector’s scale, regulatory support, and consistent earnings potential make it a strategic addition to a well-diversified portfolio.
B59: 💳Stocks of Banks🏦
D63: Valuation💰 | M63: Profitability 💸 | X63: Financial Health 🩺 | AM63: Returns 📈 | AP63: Final Value
B64: Name of the ratio | D64: P/E Ratio | F64: P/B Ratio | H64: PEG Ratio | J64: Market Cap | M64: ROE | O64: ROA | Q64: Net Interest Margin (NIM) | S64: Cost-to-Income (%) | U64: Provision for Credit Losses (PCL) (Cr) | X64: Debt-to-Equity | Z64: CASA Ratio | AB64: Loan to Asset Ratio | AD64: Loan-to-Deposit Ratios | AF64: Gross NPA Ratio | AH64: Capital Adequacy Ratio (CAR) | AJ64: Liquidity Coverage Ratio (LCR) | AM64: Dividend Yield
B65: Weight | D65: 0.06 | F65: 0.08 | H65: 0.05 | J65: 0.05 | M65: 0.1 | O65: 0.07 | Q65: 0.08 | S65: 0.04 | U65: 0.07 | X65: 0.05 | Z65: 0.05 | AB65: 0.05 | AD65: 0.05 | AF65: 0.08 | AH65: 0.05 | AJ65: 0.05 | AM65: 0.04
B66: Reason | D66: Helpful for comparing profitability across banks, but earnings can be volatile due to provisioning swings. | F66: Most critical valuation metric for banks, assets are financial, and book value closely reflects economic reality. | H66: Adds context to P/E, though banks tend to grow steadily, not exponentially. | J66: Size gives stability, brand trust, and deposit base, but fundamentals remain more important. | M66: Key indicator of how well a bank uses its capital base, high ROE signals efficient lending. | O66: Important for understanding how much profit is earned from the bank's asset base (loans, securities). | Q66: Reflects spread between lending and borrowing rates, central to banking operations. | S66: Shows how well a bank controls operating costs, lower is better, but some costs are growth investments. | U66: Indicates how much of earnings are consumed by bad loans, rising PCL is a red flag. | X66: Less meaningful in banks, but still shows aggressive capital structuring. | Z66: Higher CASA = lower cost of funds, giving banks pricing power and higher NIM. | AB66: Indicates how much of the bank’s assets are loans (earning assets), helps assess risk and returns. | AD66: Higher LDR is better because it reflects more efficient use of deposits to generate income through lending, as long as it stays within safe regulatory limits. | AF66: Directly reflects health of loan book, higher NPA = higher risk of write-offs and weaker financials. | AH66: Regulatory requirement; higher CAR = more capacity to absorb shocks and grow lending. | AJ66: Ensures the bank can survive a short-term funding crunch, especially relevant post-2008. | AM66: Useful for income, seeking investors, but less important for evaluating bank health/growth.
D67: Lower⬇️ | E67: Value Weighted | F67: Lower⬇️ | G67: Value Weighted | H67: Lower⬇️ | I67: Value Weighted | J67: Higher⬆️ | K67: Value Weighted | M67: Higher⬆️ | N67: Value Weighted | O67: Higher⬆️ | P67: Value Weighted | Q67: Higher⬆️ | R67: Value Weighted | S67: Lower⬇️ | T67: Value Weighted | U67: Lower⬇️ | V67: Value Weighted | X67: Lower⬇️ | Y67: Value Weighted | Z67: Higher⬆️ | AA67: Value Weighted | AB67: Higher⬆️ | AC67: Value Weighted | AD67: Higher⬆️ | AE67: Value Weighted | AF67: Lower⬇️ | AG67: Value Weighted | AH67: Higher⬆️ | AI67: Value Weighted | AJ67: Higher⬆️ | AK67: Value Weighted | AM67: Higher⬆️ | AN67: Value Weighted
...

Sheet Part A
B2: XAU/INR – Gold Price per Gram (INR) | N2: ICICI Bank Ltd XNSE: ICICIBANK | Z2: Indus Towers Ltd (INDUSTOWER.NS) | AL2: Hindustan Aeronautics Limited (HAL.NS) | AX2: ITC Limited (ITC.NS)
BK5: COVARIANCE MATRIX | BL5: XAU/INR – Gold Price per Gram (INR) | BM5: ICICI Bank Ltd | BN5: Indus Towers Ltd | BO5: Hindustan Aeronautics Limited | BQ5: CORRELATION MATRIX | BR5: XAU/INR – Gold Price per Gram (INR) | BS5: ICICI Bank Ltd | BT5: Indus Towers Ltd | BU5: Hindustan Aeronautics Limited
B6: Date | C6: Open | D6: High | E6: Low | F6: Close | G6: Volume | H6: Daily Returns | I6: Standard Deviation | J6: Average Return | K6: Annual Return | N6: =IFERROR(__xludf.DUMMYFUNCTION("GOOGLEFINANCE(""NSE:ICICIBANK"", ""all"", DATE(2024,4,1), DATE(2025,4,30))"),"Date") -> Date | O6: =IFERROR(__xludf.DUMMYFUNCTION("""COMPUTED_VALUE"""),"Open") -> Open | P6: =IFERROR(__xludf.DUMMYFUNCTION("""COMPUTED_VALUE"""),"High") -> High | Q6: =IFERROR(__xludf.DUMMYFUNCTION("""COMPUTED_VALUE"""),"Low") -> Low | R6: =IFERROR(__xludf.DUMMYFUNCTION("""COMPUTED_VALUE"""),"Close") -> Close | S6: =IFERROR(__xludf.DUMMYFUNCTION("""COMPUTED_VALUE"""),"Volume") -> Volume | T6: Daily Returns | U6: Standard Deviation | V6: Average Return | W6: Annual Return | Z6: =IFERROR(__xludf.DUMMYFUNCTION("GOOGLEFINANCE(""NSE:INDUSTOWER"", ""all"", DATE(2024,4,1), DATE(2025,4,30)) "),"Date") -> Date | AA6: =IFERROR(__xludf.DUMMYFUNCTION("""COMPUTED_VALUE"""),"Open") -> Open | AB6: =IFERROR(__xludf.DUMMYFUNCTION("""COMPUTED_VALUE"""),"High") -> High | AC6: =IFERROR(__xludf.DUMMYFUNCTION("""COMPUTED_VALUE"""),"Low") -> Low | AD6: =IFERROR(__xludf.DUMMYFUNCTION("""COMPUTED_VALUE"""),"Close") -> Close | AE6: =IFERROR(__xludf.DUMMYFUNCTION("""COMPUTED_VALUE"""),"Volume") -> Volume | AF6: Daily Returns | AG6: Standard Deviation | AH6: Average Return | AI6: Annual Return | AL6: =IFERROR(__xludf.DUMMYFUNCTION("GOOGLEFINANCE(""NSE:HAL"", ""all"", DATE(2024,4,1), DATE(2025,4,30))"),"Date") -> Date | AM6: =IFERROR(__xludf.DUMMYFUNCTION("""COMPUTED_VALUE"""),"Open") -> Open | AN6: =IFERROR(__xludf.DUMMYFUNCTION("""COMPUTED_VALUE"""),"High") -> High | AO6: =IFERROR(__xludf.DUMMYFUNCTION("""COMPUTED_VALUE"""),"Low") -> Low | AP6: =IFERROR(__xludf.DUMMYFUNCTION("""COMPUTED_VALUE"""),"Close") -> Close | AQ6: =IFERROR(__xludf.DUMMYFUNCTION("""COMPUTED_VALUE"""),"Volume") -> Volume | AR6: Daily Returns | AS6: Standard Deviation | AT6: Average Return | AU6: Annual Return | AX6: =IFERROR(__xludf.DUMMYFUNCTION("GOOGLEFINANCE(""NSE:ITC"", ""all"", DATE(2024,4,1), DATE(2025,4,30)) "),"Date") -> Date | AY6: =IFERROR(__xludf.DUMMYFUNCTION("""COMPUTED_VALUE"""),"Open") -> Open | AZ6: =IFERROR(__xludf.DUMMYFUNCTION("""COMPUTED_VALUE"""),"High") -> High | BA6: =IFERROR(__xludf.DUMMYFUNCTION("""COMPUTED_VALUE"""),"Low") -> Low | BB6: =IFERROR(__xludf.DUMMYFUNCTION("""COMPUTED_VALUE"""),"Close") -> Close | BC6: =IFERROR(__xludf.DUMMYFUNCTION("""COMPUTED_VALUE"""),"Volume") -> Volume | BD6: Daily Returns | BE6: Standard Deviation | BF6: Average Return | BG6: Annual Return | BI6: T-Bill RATE | BK6: XAU/INR – Gold Price per Gram (INR) | BL6: =(COVAR('Part A'!H7:H271,'Part A'!H7:H271))*(252) -> 0.028790752 | BM6: =(COVAR('Part A'!H7:H272,'Part A'!T7:T272))*(252) -> 0.0014539536 | BN6: =(COVAR('Part A'!H7:H272,'Part A'!AF7:AF272))*(252) -> 0.0058478105 | BO6: =(COVAR('Part A'!H7:H272,'Part A'!AR7:AR272))*(252) -> 0.0050895786 | BQ6: XAU/INR – Gold Price per Gram (INR) | BR6: =CORREL('Part A'!H7:H272,'Part A'!H7:H272) -> 1 | BS6: =CORREL('Part A'!H7:H272,'Part A'!T7:T272) -> 0.041214768 | BT6: =CORREL('Part A'!H7:H272,'Part A'!AF7:AF272) -> 0.092611843 | BU6: =CORREL('Part A'!H7:H272,'Part A'!AR7:AR272) -> 0.068538574
B7: 45383 | C7: 6003.51 | D7: 6072.94 | E7: 5974.12 | F7: 6033.77 | G7: - | H7: 0 | I7: =STDEV(H7:H271)*15.8745078664 -> 0.16999944 | J7: =AVERAGE(H7:H271) -> 0.0014853748 | K7: =(1 + J7)^252 - 1 -> 0.45359052 | N7: =IFERROR(__xludf.DUMMYFUNCTION("""COMPUTED_VALUE"""),45383.64583333333) -> 45383.646 | O7: =IFERROR(__xludf.DUMMYFUNCTION("""COMPUTED_VALUE"""),1096.05) -> 1096.05 | P7: =IFERROR(__xludf.DUMMYFUNCTION("""COMPUTED_VALUE"""),1102.95) -> 1102.95 | Q7: =IFERROR(__xludf.DUMMYFUNCTION("""COMPUTED_VALUE"""),1094.45) -> 1094.45 | R7: =IFERROR(__xludf.DUMMYFUNCTION("""COMPUTED_VALUE"""),1099.65) -> 1099.65 | S7: =IFERROR(__xludf.DUMMYFUNCTION("""COMPUTED_VALUE"""),1.0848191E7) -> 10848191 | T7: 0 | U7: =STDEV(T7:T271)*15.8745078664 -> 0.20830139 | V7: =AVERAGE(T7:T271) -> 0.00098332978 | W7: =(1 + V7)^252 - 1 -> 0.28104654 | Z7: =IFERROR(__xludf.DUMMYFUNCTION("""COMPUTED_VALUE"""),45383.64583333333) -> 45383.646 | AA7: =IFERROR(__xludf.DUMMYFUNCTION("""COMPUTED_VALUE"""),294.9) -> 294.9 | AB7: =IFERROR(__xludf.DUMMYFUNCTION("""COMPUTED_VALUE"""),319.5) -> 319.5 | AC7: =IFERROR(__xludf.DUMMYFUNCTION("""COMPUTED_VALUE"""),292.15) -> 292.15 | AD7: =IFERROR(__xludf.DUMMYFUNCTION("""COMPUTED_VALUE"""),315.2) -> 315.2 | AE7: =IFERROR(__xludf.DUMMYFUNCTION("""COMPUTED_VALUE"""),4.02675E7) -> 40267500 | AF7: 0 | AG7: =STDEV(AF8:AF271)*15.8745078664 -> 0.37354583 | AH7: =AVERAGE(AF7:AF271) -> 0.00097565997 | AI7: =(1 + AH7)^252 - 1 -> 0.27857535 | AL7: =IFERROR(__xludf.DUMMYFUNCTION("""COMPUTED_VALUE"""),45383.64583333333) -> 45383.646 | AM7: =IFERROR(__xludf.DUMMYFUNCTION("""COMPUTED_VALUE"""),3392.0) -> 3392 | AN7: =IFERROR(__xludf.DUMMYFUNCTION("""COMPUTED_VALUE"""),3454.25) -> 3454.25 | AO7: =IFERROR(__xludf.DUMMYFUNCTION("""COMPUTED_VALUE"""),3362.1) -> 3362.1 | AP7: =IFERROR(__xludf.DUMMYFUNCTION("""COMPUTED_VALUE"""),3403.35) -> 3403.35 | AQ7: =IFERROR(__xludf.DUMMYFUNCTION("""COMPUTED_VALUE"""),2513886.0) -> 2513886 | AR7: 0 | AS7: =STDEV(AR7:AR271)*15.8745078664 -> 0.43847136 | AT7: =AVERAGE(AR7:AR271) -> 0.0010438666 | AU7: =(1 + AT7)^252 - 1 -> 0.30071899 | AX7: =IFERROR(__xludf.DUMMYFUNCTION("""COMPUTED_VALUE"""),45383.64583333333) -> 45383.646 | AY7: =IFERROR(__xludf.DUMMYFUNCTION("""COMPUTED_VALUE"""),429.1) -> 429.1 | AZ7: =IFERROR(__xludf.DUMMYFUNCTION("""COMPUTED_VALUE"""),431.35) -> 431.35 | BA7: =IFERROR(__xludf.DUMMYFUNCTION("""COMPUTED_VALUE"""),425.75) -> 425.75 | BB7: =IFERROR(__xludf.DUMMYFUNCTION("""COMPUTED_VALUE"""),426.7) -> 426.7 | BC7: =IFERROR(__xludf.DUMMYFUNCTION("""COMPUTED_VALUE"""),9382308.0) -> 9382308 | BD7: 0 | BE7: =STDEV(BD7:BD271)*15.8745078664 -> 0.19804371 | BF7: =AVERAGE(BD7:BD271) -> -7.9676896e-06 | BG7: =(1 + BF7)^252 - 1 -> -0.0020058514 | BI7: 0.0586 | BK7: ICICI Bank Ltd | BL7: =(COVAR('Part A'!H7:H272,'Part A'!T7:T272))*(252) -> 0.0014539536 | BM7: =(COVAR('Part A'!T7:T271,'Part A'!T7:T271))*(252) -> 0.043225734 | BN7: =(COVAR('Part A'!T7:T272,'Part A'!AF7:AF272))*(252) -> 0.031250305 | BO7: =(COVAR('Part A'!T7:T272,'Part A'!AR7:AR272))*(252) -> 0.03469537 | BQ7: ICICI Bank Ltd | BR7: =CORREL('Part A'!H7:H272,'Part A'!T7:T272) -> 0.041214768 | BS7: =CORREL('Part A'!T7:T272,'Part A'!T7:T272) -> 1 | BT7: =CORREL('Part A'!AF7:AF272,'Part A'!T7:T272) -> 0.40390834 | BU7: =CORREL('Part A'!AR7:AR272,'Part A'!T7:T272) -> 0.38131166
B8: 45384 | C8: 6036.07 | D8: 6112.94 | E8: 6022.03 | F8: 6107.29 | G8: - | H8: =LN(F8/F7) -> 0.012111117 | N8: =IFERROR(__xludf.DUMMYFUNCTION("""COMPUTED_VALUE"""),45384.64583333333) -> 45384.646 | O8: =IFERROR(__xludf.DUMMYFUNCTION("""COMPUTED_VALUE"""),1094.45) -> 1094.45 | P8: =IFERROR(__xludf.DUMMYFUNCTION("""COMPUTED_VALUE"""),1094.45) -> 1094.45 | Q8: =IFERROR(__xludf.DUMMYFUNCTION("""COMPUTED_VALUE"""),1079.25) -> 1079.25 | R8: =IFERROR(__xludf.DUMMYFUNCTION("""COMPUTED_VALUE"""),1081.2) -> 1081.2 | S8: =IFERROR(__xludf.DUMMYFUNCTION("""COMPUTED_VALUE"""),1.4380396E7) -> 14380396 | T8: =LN(R8/R7) -> -0.016920412 | Z8: =IFERROR(__xludf.DUMMYFUNCTION("""COMPUTED_VALUE"""),45384.64583333333) -> 45384.646 | AA8: =IFERROR(__xludf.DUMMYFUNCTION("""COMPUTED_VALUE"""),314.5) -> 314.5 | AB8: =IFERROR(__xludf.DUMMYFUNCTION("""COMPUTED_VALUE"""),314.5) -> 314.5 | AC8: =IFERROR(__xludf.DUMMYFUNCTION("""COMPUTED_VALUE"""),303.65) -> 303.65 | AD8: =IFERROR(__xludf.DUMMYFUNCTION("""COMPUTED_VALUE"""),304.75) -> 304.75 | AE8: =IFERROR(__xludf.DUMMYFUNCTION("""COMPUTED_VALUE"""),1.8843574E7) -> 18843574 | AF8: =LN(AD8/AD7) -> -0.03371559 | AL8: =IFERROR(__xludf.DUMMYFUNCTION("""COMPUTED_VALUE"""),45384.64583333333) -> 45384.646 | AM8: =IFERROR(__xludf.DUMMYFUNCTION("""COMPUTED_VALUE"""),3440.0) -> 3440 | AN8: =IFERROR(__xludf.DUMMYFUNCTION("""COMPUTED_VALUE"""),3584.0) -> 3584 | AO8: =IFERROR(__xludf.DUMMYFUNCTION("""COMPUTED_VALUE"""),3412.0) -> 3412 | AP8: =IFERROR(__xludf.DUMMYFUNCTION("""COMPUTED_VALUE"""),3543.0) -> 3543 | AQ8: =IFERROR(__xludf.DUMMYFUNCTION("""COMPUTED_VALUE"""),3169551.0) -> 3169551 | AR8: =LN(AP8/AP7) -> 0.040213585 | AX8: =IFERROR(__xludf.DUMMYFUNCTION("""COMPUTED_VALUE"""),45384.64583333333) -> 45384.646 | AY8: =IFERROR(__xludf.DUMMYFUNCTION("""COMPUTED_VALUE"""),428.7) -> 428.7 | AZ8: =IFERROR(__xludf.DUMMYFUNCTION("""COMPUTED_VALUE"""),428.7) -> 428.7 | BA8: =IFERROR(__xludf.DUMMYFUNCTION("""COMPUTED_VALUE"""),424.6) -> 424.6 | BB8: =IFERROR(__xludf.DUMMYFUNCTION("""COMPUTED_VALUE"""),425.85) -> 425.85 | BC8: =IFERROR(__xludf.DUMMYFUNCTION("""COMPUTED_VALUE"""),8853678.0) -> 8853678 | BD8: =LN(BB8/BB7) -> -0.0019940186 | BK8: Indus Towers Ltd | BL8: =(COVAR('Part A'!H7:H272,'Part A'!AF7:AF272))*(252) -> 0.0058478105 | BM8: =(COVAR('Part A'!T7:T272,'Part A'!AF7:AF272))*(252) -> 0.031250305 | BN8: =(COVAR('Part A'!AF7:AF272,'Part A'!AF7:AF272))*(252) -> 0.13848429 | BO8: =(COVAR('Part A'!AF7:AF272,'Part A'!AR7:AR272))*(252) -> 0.074433701 | BQ8: Indus Towers Ltd | BR8: =CORREL('Part A'!AF7:AF272,'Part A'!H7:H272) -> 0.092611843 | BS8: =CORREL('Part A'!AF7:AF272,'Part A'!T7:T272) -> 0.40390834 | BT8: =CORREL('Part A'!AF7:AF272,'Part A'!AF7:AF272) -> 1 | BU8: =CORREL('Part A'!AF7:AF272,'Part A'!AR7:AR272) -> 0.45703462
B9: 45385 | C9: 6110.08 | D9: 6178.04 | E9: 6082.12 | F9: 6171.38 | G9: - | H9: =LN(F9/F8) -> 0.010439336 | N9: =IFERROR(__xludf.DUMMYFUNCTION("""COMPUTED_VALUE"""),45385.64583333333) -> 45385.646 | O9: =IFERROR(__xludf.DUMMYFUNCTION("""COMPUTED_VALUE"""),1075.0) -> 1075 | P9: =IFERROR(__xludf.DUMMYFUNCTION("""COMPUTED_VALUE"""),1083.65) -> 1083.65 | Q9: =IFERROR(__xludf.DUMMYFUNCTION("""COMPUTED_VALUE"""),1072.25) -> 1072.25 | R9: =IFERROR(__xludf.DUMMYFUNCTION("""COMPUTED_VALUE"""),1077.2) -> 1077.2 | S9: =IFERROR(__xludf.DUMMYFUNCTION("""COMPUTED_VALUE"""),1.5477184E7) -> 15477184 | T9: =LN(R9/R8) -> -0.0037064535 | Z9: =IFERROR(__xludf.DUMMYFUNCTION("""COMPUTED_VALUE"""),45385.64583333333) -> 45385.646 | AA9: =IFERROR(__xludf.DUMMYFUNCTION("""COMPUTED_VALUE"""),304.8) -> 304.8 | AB9: =IFERROR(__xludf.DUMMYFUNCTION("""COMPUTED_VALUE"""),307.4) -> 307.4 | AC9: =IFERROR(__xludf.DUMMYFUNCTION("""COMPUTED_VALUE"""),298.4) -> 298.4 | AD9: =IFERROR(__xludf.DUMMYFUNCTION("""COMPUTED_VALUE"""),300.55) -> 300.55 | AE9: =IFERROR(__xludf.DUMMYFUNCTION("""COMPUTED_VALUE"""),2.1197899E7) -> 21197899 | AF9: =LN(AD9/AD8) -> -0.013877639 | AL9: =IFERROR(__xludf.DUMMYFUNCTION("""COMPUTED_VALUE"""),45385.64583333333) -> 45385.646 | AM9: =IFERROR(__xludf.DUMMYFUNCTION("""COMPUTED_VALUE"""),3540.0) -> 3540 | AN9: =IFERROR(__xludf.DUMMYFUNCTION("""COMPUTED_VALUE"""),3610.8) -> 3610.8 | AO9: =IFERROR(__xludf.DUMMYFUNCTION("""COMPUTED_VALUE"""),3508.3) -> 3508.3 | AP9: =IFERROR(__xludf.DUMMYFUNCTION("""COMPUTED_VALUE"""),3589.3) -> 3589.3 | AQ9: =IFERROR(__xludf.DUMMYFUNCTION("""COMPUTED_VALUE"""),2077663.0) -> 2077663 | AR9: =LN(AP9/AP8) -> 0.012983372 | AX9: =IFERROR(__xludf.DUMMYFUNCTION("""COMPUTED_VALUE"""),45385.64583333333) -> 45385.646 | AY9: =IFERROR(__xludf.DUMMYFUNCTION("""COMPUTED_VALUE"""),426.0) -> 426 | AZ9: =IFERROR(__xludf.DUMMYFUNCTION("""COMPUTED_VALUE"""),428.8) -> 428.8 | BA9: =IFERROR(__xludf.DUMMYFUNCTION("""COMPUTED_VALUE"""),421.0) -> 421 | BB9: =IFERROR(__xludf.DUMMYFUNCTION("""COMPUTED_VALUE"""),425.2) -> 425.2 | BC9: =IFERROR(__xludf.DUMMYFUNCTION("""COMPUTED_VALUE"""),1.266452E7) -> 12664520 | BD9: =LN(BB9/BB8) -> -0.0015275251 | BK9: Hindustan Aeronautics Limited | BL9: =(COVAR('Part A'!H7:H272,'Part A'!AR7:AR272))*(252) -> 0.0050895786 | BM9: =(COVAR('Part A'!T7:T272,'Part A'!AR7:AR272))*(252) -> 0.03469537 | BN9: =(COVAR('Part A'!AF7:AF272,'Part A'!AR7:AR272))*(252) -> 0.074433701 | BO9: =(COVAR('Part A'!AR7:AR272,'Part A'!AR7:AR272))*(252) -> 0.19153163 | BQ9: Hindustan Aeronautics Limited | BR9: =CORREL('Part A'!H7:H272,'Part A'!AR7:AR272) -> 0.068538574 | BS9: =CORREL('Part A'!T7:T272,'Part A'!AR7:AR272) -> 0.38131166 | BT9: =CORREL('Part A'!AF7:AF272,'Part A'!AR7:AR272) -> 0.45703462 | BU9: =CORREL('Part A'!AR7:AR272,'Part A'!AR7:AR272) -> 1
B10: 45386 | C10: 6173.52 | D10: 6183.24 | E10: 6111.03 | F10: 6136.13 | G10: - | H10: =LN(F10/F9) -> -0.0057282255 | N10: =IFERROR(__xludf.DUMMYFUNCTION("""COMPUTED_VALUE"""),45386.64583333333) -> 45386.646 | O10: =IFERROR(__xludf.DUMMYFUNCTION("""COMPUTED_VALUE"""),1084.75) -> 1084.75 | P10: =IFERROR(__xludf.DUMMYFUNCTION("""COMPUTED_VALUE"""),1085.8) -> 1085.8 | Q10: =IFERROR(__xludf.DUMMYFUNCTION("""COMPUTED_VALUE"""),1063.45) -> 1063.45 | R10: =IFERROR(__xludf.DUMMYFUNCTION("""COMPUTED_VALUE"""),1078.85) -> 1078.85 | S10: =IFERROR(__xludf.DUMMYFUNCTION("""COMPUTED_VALUE"""),2.1419689E7) -> 21419689 | T10: =LN(R10/R9) -> 0.001530577 | Z10: =IFERROR(__xludf.DUMMYFUNCTION("""COMPUTED_VALUE"""),45386.64583333333) -> 45386.646 | AA10: =IFERROR(__xludf.DUMMYFUNCTION("""COMPUTED_VALUE"""),304.05) -> 304.05 | AB10: =IFERROR(__xludf.DUMMYFUNCTION("""COMPUTED_VALUE"""),310.0) -> 310 | AC10: =IFERROR(__xludf.DUMMYFUNCTION("""COMPUTED_VALUE"""),301.55) -> 301.55 | AD10: =IFERROR(__xludf.DUMMYFUNCTION("""COMPUTED_VALUE"""),306.6) -> 306.6 | AE10: =IFERROR(__xludf.DUMMYFUNCTION("""COMPUTED_VALUE"""),1.38752E7) -> 13875200 | AF10: =LN(AD10/AD9) -> 0.019929837 | AL10: =IFERROR(__xludf.DUMMYFUNCTION("""COMPUTED_VALUE"""),45386.64583333333) -> 45386.646 | AM10: =IFERROR(__xludf.DUMMYFUNCTION("""COMPUTED_VALUE"""),3609.95) -> 3609.95 | AN10: =IFERROR(__xludf.DUMMYFUNCTION("""COMPUTED_VALUE"""),3614.95) -> 3614.95 | AO10: =IFERROR(__xludf.DUMMYFUNCTION("""COMPUTED_VALUE"""),3512.2) -> 3512.2 | AP10: =IFERROR(__xludf.DUMMYFUNCTION("""COMPUTED_VALUE"""),3540.95) -> 3540.95 | AQ10: =IFERROR(__xludf.DUMMYFUNCTION("""COMPUTED_VALUE"""),1591827.0) -> 1591827 | AR10: =LN(AP10/AP9) -> -0.013562145 | AX10: =IFERROR(__xludf.DUMMYFUNCTION("""COMPUTED_VALUE"""),45386.64583333333) -> 45386.646 | AY10: =IFERROR(__xludf.DUMMYFUNCTION("""COMPUTED_VALUE"""),425.55) -> 425.55 | AZ10: =IFERROR(__xludf.DUMMYFUNCTION("""COMPUTED_VALUE"""),427.35) -> 427.35 | BA10: =IFERROR(__xludf.DUMMYFUNCTION("""COMPUTED_VALUE"""),419.9) -> 419.9 | BB10: =IFERROR(__xludf.DUMMYFUNCTION("""COMPUTED_VALUE"""),422.75) -> 422.75 | BC10: =IFERROR(__xludf.DUMMYFUNCTION("""COMPUTED_VALUE"""),1.835841E7) -> 18358410 | BD10: =LN(BB10/BB9) -> -0.0057786587
B11: 45387 | C11: 6138.98 | D11: 6242.15 | E11: 6084.12 | F11: 6237.71 | G11: - | H11: =LN(F11/F10) -> 0.016418878 | N11: =IFERROR(__xludf.DUMMYFUNCTION("""COMPUTED_VALUE"""),45387.64583333333) -> 45387.646 | O11: =IFERROR(__xludf.DUMMYFUNCTION("""COMPUTED_VALUE"""),1070.0) -> 1070 | P11: =IFERROR(__xludf.DUMMYFUNCTION("""COMPUTED_VALUE"""),1086.0) -> 1086 | Q11: =IFERROR(__xludf.DUMMYFUNCTION("""COMPUTED_VALUE"""),1067.45) -> 1067.45 | R11: =IFERROR(__xludf.DUMMYFUNCTION("""COMPUTED_VALUE"""),1083.4) -> 1083.4 | S11: =IFERROR(__xludf.DUMMYFUNCTION("""COMPUTED_VALUE"""),1.5340637E7) -> 15340637 | T11: =LN(R11/R10) -> 0.0042085852 | Z11: =IFERROR(__xludf.DUMMYFUNCTION("""COMPUTED_VALUE"""),45387.64583333333) -> 45387.646 | AA11: =IFERROR(__xludf.DUMMYFUNCTION("""COMPUTED_VALUE"""),305.95) -> 305.95 | AB11: =IFERROR(__xludf.DUMMYFUNCTION("""COMPUTED_VALUE"""),321.55) -> 321.55 | AC11: =IFERROR(__xludf.DUMMYFUNCTION("""COMPUTED_VALUE"""),302.1) -> 302.1 | AD11: =IFERROR(__xludf.DUMMYFUNCTION("""COMPUTED_VALUE"""),314.0) -> 314 | AE11: =IFERROR(__xludf.DUMMYFUNCTION("""COMPUTED_VALUE"""),2.1960872E7) -> 21960872 | AF11: =LN(AD11/AD10) -> 0.023849019 | AL11: =IFERROR(__xludf.DUMMYFUNCTION("""COMPUTED_VALUE"""),45387.64583333333) -> 45387.646 | AM11: =IFERROR(__xludf.DUMMYFUNCTION("""COMPUTED_VALUE"""),3545.0) -> 3545 | AN11: =IFERROR(__xludf.DUMMYFUNCTION("""COMPUTED_VALUE"""),3595.0) -> 3595 | AO11: =IFERROR(__xludf.DUMMYFUNCTION("""COMPUTED_VALUE"""),3507.85) -> 3507.85 | AP11: =IFERROR(__xludf.DUMMYFUNCTION("""COMPUTED_VALUE"""),3586.05) -> 3586.05 | AQ11: =IFERROR(__xludf.DUMMYFUNCTION("""COMPUTED_VALUE"""),1123258.0) -> 1123258 | AR11: =LN(AP11/AP10) -> 0.012656265 | AX11: =IFERROR(__xludf.DUMMYFUNCTION("""COMPUTED_VALUE"""),45387.64583333333) -> 45387.646 | AY11: =IFERROR(__xludf.DUMMYFUNCTION("""COMPUTED_VALUE"""),422.5) -> 422.5 | AZ11: =IFERROR(__xludf.DUMMYFUNCTION("""COMPUTED_VALUE"""),431.7) -> 431.7 | BA11: =IFERROR(__xludf.DUMMYFUNCTION("""COMPUTED_VALUE"""),419.95) -> 419.95 | BB11: =IFERROR(__xludf.DUMMYFUNCTION("""COMPUTED_VALUE"""),427.55) -> 427.55 | BC11: =IFERROR(__xludf.DUMMYFUNCTION("""COMPUTED_VALUE"""),1.6147032E7) -> 16147032 | BD11: =LN(BB11/BB10) -> 0.011290253 | BK11: COVARIANCE MATRIX | BL11: XAU/INR – Gold Price per Gram (INR) | BM11: ICICI Bank Ltd | BN11: Indus Towers Ltd | BO11: Hindustan Aeronautics Limited | BQ11: EQUALLY WEIGHTED
B12: 45390 | C12: 6219.67 | D12: 6302.78 | E12: 6168.43 | F12: 6260.67 | G12: - | H12: =LN(F12/F11) -> 0.0036740803 | N12: =IFERROR(__xludf.DUMMYFUNCTION("""COMPUTED_VALUE"""),45390.64583333333) -> 45390.646 | O12: =IFERROR(__xludf.DUMMYFUNCTION("""COMPUTED_VALUE"""),1078.35) -> 1078.35 | P12: =IFERROR(__xludf.DUMMYFUNCTION("""COMPUTED_VALUE"""),1091.75) -> 1091.75 | Q12: =IFERROR(__xludf.DUMMYFUNCTION("""COMPUTED_VALUE"""),1076.3) -> 1076.3 | R12: =IFERROR(__xludf.DUMMYFUNCTION("""COMPUTED_VALUE"""),1087.15) -> 1087.15 | S12: =IFERROR(__xludf.DUMMYFUNCTION("""COMPUTED_VALUE"""),8023461.0) -> 8023461 | T12: =LN(R12/R11) -> 0.0034553489 | Z12: =IFERROR(__xludf.DUMMYFUNCTION("""COMPUTED_VALUE"""),45390.64583333333) -> 45390.646 | AA12: =IFERROR(__xludf.DUMMYFUNCTION("""COMPUTED_VALUE"""),316.5) -> 316.5 | AB12: =IFERROR(__xludf.DUMMYFUNCTION("""COMPUTED_VALUE"""),331.5) -> 331.5 | AC12: =IFERROR(__xludf.DUMMYFUNCTION("""COMPUTED_VALUE"""),315.95) -> 315.95 | AD12: =IFERROR(__xludf.DUMMYFUNCTION("""COMPUTED_VALUE"""),327.8) -> 327.8 | AE12: =IFERROR(__xludf.DUMMYFUNCTION("""COMPUTED_VALUE"""),2.8736885E7) -> 28736885 | AF12: =LN(AD12/AD11) -> 0.04301068 | AL12: =IFERROR(__xludf.DUMMYFUNCTION("""COMPUTED_VALUE"""),45390.64583333333) -> 45390.646 | AM12: =IFERROR(__xludf.DUMMYFUNCTION("""COMPUTED_VALUE"""),3600.0) -> 3600 | AN12: =IFERROR(__xludf.DUMMYFUNCTION("""COMPUTED_VALUE"""),3600.0) -> 3600 | AO12: =IFERROR(__xludf.DUMMYFUNCTION("""COMPUTED_VALUE"""),3543.05) -> 3543.05 | AP12: =IFERROR(__xludf.DUMMYFUNCTION("""COMPUTED_VALUE"""),3567.15) -> 3567.15 | AQ12: =IFERROR(__xludf.DUMMYFUNCTION("""COMPUTED_VALUE"""),865339.0) -> 865339 | AR12: =LN(AP12/AP11) -> -0.0052843606 | AX12: =IFERROR(__xludf.DUMMYFUNCTION("""COMPUTED_VALUE"""),45390.64583333333) -> 45390.646 | AY12: =IFERROR(__xludf.DUMMYFUNCTION("""COMPUTED_VALUE"""),428.3) -> 428.3 | AZ12: =IFERROR(__xludf.DUMMYFUNCTION("""COMPUTED_VALUE"""),431.4) -> 431.4 | BA12: =IFERROR(__xludf.DUMMYFUNCTION("""COMPUTED_VALUE"""),427.75) -> 427.75 | BB12: =IFERROR(__xludf.DUMMYFUNCTION("""COMPUTED_VALUE"""),429.1) -> 429.1 | BC12: =IFERROR(__xludf.DUMMYFUNCTION("""COMPUTED_VALUE"""),8516632.0) -> 8516632 | BD12: =LN(BB12/BB11) -> 0.0036187514 | BK12: XAU/INR – Gold Price per Gram (INR) | BL12: 0.028790752 | BM12: 0.0014539536 | BN12: 0.0058478105 | BO12: 0.0050895786
B13: 45391 | C13: 6262.85 | D13: 6328.57 | E13: 6254.18 | F13: 6291.41 | G13: - | H13: =LN(F13/F12) -> 0.0048980028 | N13: =IFERROR(__xludf.DUMMYFUNCTION("""COMPUTED_VALUE"""),45391.64583333333) -> 45391.646 | O13: =IFERROR(__xludf.DUMMYFUNCTION("""COMPUTED_VALUE"""),1091.95) -> 1091.95 | P13: =IFERROR(__xludf.DUMMYFUNCTION("""COMPUTED_VALUE"""),1115.25) -> 1115.25 | Q13: =IFERROR(__xludf.DUMMYFUNCTION("""COMPUTED_VALUE"""),1088.3) -> 1088.3 | R13: =IFERROR(__xludf.DUMMYFUNCTION("""COMPUTED_VALUE"""),1107.05) -> 1107.05 | S13: =IFERROR(__xludf.DUMMYFUNCTION("""COMPUTED_VALUE"""),1.2298463E7) -> 12298463 | T13: =LN(R13/R12) -> 0.018139227 | Z13: =IFERROR(__xludf.DUMMYFUNCTION("""COMPUTED_VALUE"""),45391.64583333333) -> 45391.646 | AA13: =IFERROR(__xludf.DUMMYFUNCTION("""COMPUTED_VALUE"""),328.5) -> 328.5 | AB13: =IFERROR(__xludf.DUMMYFUNCTION("""COMPUTED_VALUE"""),331.0) -> 331 | AC13: =IFERROR(__xludf.DUMMYFUNCTION("""COMPUTED_VALUE"""),324.2) -> 324.2 | AD13: =IFERROR(__xludf.DUMMYFUNCTION("""COMPUTED_VALUE"""),328.0) -> 328 | AE13: =IFERROR(__xludf.DUMMYFUNCTION("""COMPUTED_VALUE"""),1.3705541E7) -> 13705541 | AF13: =LN(AD13/AD12) -> 0.00060994207 | AL13: =IFERROR(__xludf.DUMMYFUNCTION("""COMPUTED_VALUE"""),45391.64583333333) -> 45391.646 | AM13: =IFERROR(__xludf.DUMMYFUNCTION("""COMPUTED_VALUE"""),3568.0) -> 3568 | AN13: =IFERROR(__xludf.DUMMYFUNCTION("""COMPUTED_VALUE"""),3589.0) -> 3589 | AO13: =IFERROR(__xludf.DUMMYFUNCTION("""COMPUTED_VALUE"""),3527.0) -> 3527 | AP13: =IFERROR(__xludf.DUMMYFUNCTION("""COMPUTED_VALUE"""),3546.55) -> 3546.55 | AQ13: =IFERROR(__xludf.DUMMYFUNCTION("""COMPUTED_VALUE"""),649755.0) -> 649755 | AR13: =LN(AP13/AP12) -> -0.0057916577 | AX13: =IFERROR(__xludf.DUMMYFUNCTION("""COMPUTED_VALUE"""),45391.64583333333) -> 45391.646 | AY13: =IFERROR(__xludf.DUMMYFUNCTION("""COMPUTED_VALUE"""),430.45) -> 430.45 | AZ13: =IFERROR(__xludf.DUMMYFUNCTION("""COMPUTED_VALUE"""),431.5) -> 431.5 | BA13: =IFERROR(__xludf.DUMMYFUNCTION("""COMPUTED_VALUE"""),425.55) -> 425.55 | BB13: =IFERROR(__xludf.DUMMYFUNCTION("""COMPUTED_VALUE"""),426.35) -> 426.35 | BC13: =IFERROR(__xludf.DUMMYFUNCTION("""COMPUTED_VALUE"""),6708894.0) -> 6708894 | BD13: =LN(BB13/BB12) -> -0.0064293868 | BK13: ICICI Bank Ltd | BL13: 0.0014539536 | BM13: 0.043225734 | BN13: 0.031250305 | BO13: 0.03469537 | BQ13: COMPANY | BR13: XAU/INR – Gold Price per Gram (INR) | BS13: ICICI Bank Ltd | BT13: Indus Towers Ltd | BU13: Hindustan Aeronautics Limited
B14: 45392 | C14: 6293.12 | D14: 6314.96 | E14: 6218.03 | F14: 6254.62 | G14: - | H14: =LN(F14/F13) -> -0.0058648203 | N14: =IFERROR(__xludf.DUMMYFUNCTION("""COMPUTED_VALUE"""),45392.64583333333) -> 45392.646 | O14: =IFERROR(__xludf.DUMMYFUNCTION("""COMPUTED_VALUE"""),1110.95) -> 1110.95 | P14: =IFERROR(__xludf.DUMMYFUNCTION("""COMPUTED_VALUE"""),1116.55) -> 1116.55 | Q14: =IFERROR(__xludf.DUMMYFUNCTION("""COMPUTED_VALUE"""),1105.15) -> 1105.15 | R14: =IFERROR(__xludf.DUMMYFUNCTION("""COMPUTED_VALUE"""),1109.4) -> 1109.4 | S14: =IFERROR(__xludf.DUMMYFUNCTION("""COMPUTED_VALUE"""),1.0598E7) -> 10598000 | T14: =LN(R14/R13) -> 0.0021205088 | Z14: =IFERROR(__xludf.DUMMYFUNCTION("""COMPUTED_VALUE"""),45392.64583333333) -> 45392.646 | AA14: =IFERROR(__xludf.DUMMYFUNCTION("""COMPUTED_VALUE"""),325.0) -> 325 | AB14: =IFERROR(__xludf.DUMMYFUNCTION("""COMPUTED_VALUE"""),330.0) -> 330 | AC14: =IFERROR(__xludf.DUMMYFUNCTION("""COMPUTED_VALUE"""),317.15) -> 317.15 | AD14: =IFERROR(__xludf.DUMMYFUNCTION("""COMPUTED_VALUE"""),326.7) -> 326.7 | AE14: =IFERROR(__xludf.DUMMYFUNCTION("""COMPUTED_VALUE"""),1.7295594E7) -> 17295594 | AF14: =LN(AD14/AD13) -> -0.0039712898 | AL14: =IFERROR(__xludf.DUMMYFUNCTION("""COMPUTED_VALUE"""),45392.64583333333) -> 45392.646 | AM14: =IFERROR(__xludf.DUMMYFUNCTION("""COMPUTED_VALUE"""),3550.0) -> 3550 | AN14: =IFERROR(__xludf.DUMMYFUNCTION("""COMPUTED_VALUE"""),3623.6) -> 3623.6 | AO14: =IFERROR(__xludf.DUMMYFUNCTION("""COMPUTED_VALUE"""),3548.65) -> 3548.65 | AP14: =IFERROR(__xludf.DUMMYFUNCTION("""COMPUTED_VALUE"""),3565.4) -> 3565.4 | AQ14: =IFERROR(__xludf.DUMMYFUNCTION("""COMPUTED_VALUE"""),1160813.0) -> 1160813 | AR14: =LN(AP14/AP13) -> 0.0053009496 | AX14: =IFERROR(__xludf.DUMMYFUNCTION("""COMPUTED_VALUE"""),45392.64583333333) -> 45392.646 | AY14: =IFERROR(__xludf.DUMMYFUNCTION("""COMPUTED_VALUE"""),428.3) -> 428.3 | AZ14: =IFERROR(__xludf.DUMMYFUNCTION("""COMPUTED_VALUE"""),437.8) -> 437.8 | BA14: =IFERROR(__xludf.DUMMYFUNCTION("""COMPUTED_VALUE"""),425.75) -> 425.75 | BB14: =IFERROR(__xludf.DUMMYFUNCTION("""COMPUTED_VALUE"""),436.95) -> 436.95 | BC14: =IFERROR(__xludf.DUMMYFUNCTION("""COMPUTED_VALUE"""),1.4008124E7) -> 14008124 | BD14: =LN(BB14/BB13) -> 0.024558167 | BK14: Indus Towers Ltd | BL14: 0.0058478105 | BM14: 0.031250305 | BN14: 0.13848429 | BO14: 0.074433701 | BQ14: Weights | BR14: 0.25 | BS14: 0.25 | BT14: 0.25 | BU14: 0.25
B15: 45394 | C15: 6354.25 | D15: 6534.13 | E15: 6270.12 | F15: 6292.97 | G15: - | H15: =LN(F15/F14) -> 0.0061127467 | N15: =IFERROR(__xludf.DUMMYFUNCTION("""COMPUTED_VALUE"""),45394.64583333333) -> 45394.646 | O15: =IFERROR(__xludf.DUMMYFUNCTION("""COMPUTED_VALUE"""),1103.5) -> 1103.5 | P15: =IFERROR(__xludf.DUMMYFUNCTION("""COMPUTED_VALUE"""),1111.85) -> 1111.85 | Q15: =IFERROR(__xludf.DUMMYFUNCTION("""COMPUTED_VALUE"""),1095.8) -> 1095.8 | R15: =IFERROR(__xludf.DUMMYFUNCTION("""COMPUTED_VALUE"""),1104.4) -> 1104.4 | S15: =IFERROR(__xludf.DUMMYFUNCTION("""COMPUTED_VALUE"""),1.2216657E7) -> 12216657 | T15: =LN(R15/R14) -> -0.0045171276 | Z15: =IFERROR(__xludf.DUMMYFUNCTION("""COMPUTED_VALUE"""),45394.64583333333) -> 45394.646 | AA15: =IFERROR(__xludf.DUMMYFUNCTION("""COMPUTED_VALUE"""),331.9) -> 331.9 | AB15: =IFERROR(__xludf.DUMMYFUNCTION("""COMPUTED_VALUE"""),336.0) -> 336 | AC15: =IFERROR(__xludf.DUMMYFUNCTION("""COMPUTED_VALUE"""),323.7) -> 323.7 | AD15: =IFERROR(__xludf.DUMMYFUNCTION("""COMPUTED_VALUE"""),328.05) -> 328.05 | AE15: =IFERROR(__xludf.DUMMYFUNCTION("""COMPUTED_VALUE"""),2.0855397E7) -> 20855397 | AF15: =LN(AD15/AD14) -> 0.0041237172 | AL15: =IFERROR(__xludf.DUMMYFUNCTION("""COMPUTED_VALUE"""),45394.64583333333) -> 45394.646 | AM15: =IFERROR(__xludf.DUMMYFUNCTION("""COMPUTED_VALUE"""),3565.0) -> 3565 | AN15: =IFERROR(__xludf.DUMMYFUNCTION("""COMPUTED_VALUE"""),3677.55) -> 3677.55 | AO15: =IFERROR(__xludf.DUMMYFUNCTION("""COMPUTED_VALUE"""),3550.0) -> 3550 | AP15: =IFERROR(__xludf.DUMMYFUNCTION("""COMPUTED_VALUE"""),3638.1) -> 3638.1 | AQ15: =IFERROR(__xludf.DUMMYFUNCTION("""COMPUTED_VALUE"""),3042596.0) -> 3042596 | AR15: =LN(AP15/AP14) -> 0.020185318 | AX15: =IFERROR(__xludf.DUMMYFUNCTION("""COMPUTED_VALUE"""),45394.64583333333) -> 45394.646 | AY15: =IFERROR(__xludf.DUMMYFUNCTION("""COMPUTED_VALUE"""),435.0) -> 435 | AZ15: =IFERROR(__xludf.DUMMYFUNCTION("""COMPUTED_VALUE"""),435.75) -> 435.75 | BA15: =IFERROR(__xludf.DUMMYFUNCTION("""COMPUTED_VALUE"""),428.3) -> 428.3 | BB15: =IFERROR(__xludf.DUMMYFUNCTION("""COMPUTED_VALUE"""),430.1) -> 430.1 | BC15: =IFERROR(__xludf.DUMMYFUNCTION("""COMPUTED_VALUE"""),1.8088372E7) -> 18088372 | BD15: =LN(BB15/BB14) -> -0.015801032 | BK15: Hindustan Aeronautics Limited | BL15: 0.0050895786 | BM15: 0.03469537 | BN15: 0.074433701 | BO15: 0.19153163 | BQ15: Annual Return | BR15: =(1 + 'Part A'!$J$7)^252 - 1 -> 0.45359052 | BS15: =(1 + 'Part A'!$V$7)^252 - 1 -> 0.28104654 | BT15: =(1 + 'Part A'!$AH$7)^252 - 1 -> 0.27857535 | BU15: =(1 + 'Part A'!$AT$7)^252 - 1 -> 0.30071899
B16: 45397 | C16: 6296.74 | D16: 6410.33 | E16: 6239.58 | F16: 6393.08 | G16: - | H16: =LN(F16/F15) -> 0.015783018 | N16: =IFERROR(__xludf.DUMMYFUNCTION("""COMPUTED_VALUE"""),45397.64583333333) -> 45397.646 | O16: =IFERROR(__xludf.DUMMYFUNCTION("""COMPUTED_VALUE"""),1100.2) -> 1100.2 | P16: =IFERROR(__xludf.DUMMYFUNCTION("""COMPUTED_VALUE"""),1106.15) -> 1106.15 | Q16: =IFERROR(__xludf.DUMMYFUNCTION("""COMPUTED_VALUE"""),1076.6) -> 1076.6 | R16: =IFERROR(__xludf.DUMMYFUNCTION("""COMPUTED_VALUE"""),1078.35) -> 1078.35 | S16: =IFERROR(__xludf.DUMMYFUNCTION("""COMPUTED_VALUE"""),1.0526597E7) -> 10526597 | T16: =LN(R16/R15) -> -0.023870106 | Z16: =IFERROR(__xludf.DUMMYFUNCTION("""COMPUTED_VALUE"""),45397.64583333333) -> 45397.646 | AA16: =IFERROR(__xludf.DUMMYFUNCTION("""COMPUTED_VALUE"""),322.35) -> 322.35 | AB16: =IFERROR(__xludf.DUMMYFUNCTION("""COMPUTED_VALUE"""),337.75) -> 337.75 | AC16: =IFERROR(__xludf.DUMMYFUNCTION("""COMPUTED_VALUE"""),322.25) -> 322.25 | AD16: =IFERROR(__xludf.DUMMYFUNCTION("""COMPUTED_VALUE"""),334.55) -> 334.55 | AE16: =IFERROR(__xludf.DUMMYFUNCTION("""COMPUTED_VALUE"""),1.54309E7) -> 15430900 | AF16: =LN(AD16/AD15) -> 0.019620309 | AL16: =IFERROR(__xludf.DUMMYFUNCTION("""COMPUTED_VALUE"""),45397.64583333333) -> 45397.646 | AM16: =IFERROR(__xludf.DUMMYFUNCTION("""COMPUTED_VALUE"""),3640.0) -> 3640 | AN16: =IFERROR(__xludf.DUMMYFUNCTION("""COMPUTED_VALUE"""),3700.0) -> 3700 | AO16: =IFERROR(__xludf.DUMMYFUNCTION("""COMPUTED_VALUE"""),3564.05) -> 3564.05 | AP16: =IFERROR(__xludf.DUMMYFUNCTION("""COMPUTED_VALUE"""),3629.25) -> 3629.25 | AQ16: =IFERROR(__xludf.DUMMYFUNCTION("""COMPUTED_VALUE"""),3848159.0) -> 3848159 | AR16: =LN(AP16/AP15) -> -0.002435552 | AX16: =IFERROR(__xludf.DUMMYFUNCTION("""COMPUTED_VALUE"""),45397.64583333333) -> 45397.646 | AY16: =IFERROR(__xludf.DUMMYFUNCTION("""COMPUTED_VALUE"""),428.0) -> 428 | AZ16: =IFERROR(__xludf.DUMMYFUNCTION("""COMPUTED_VALUE"""),429.15) -> 429.15 | BA16: =IFERROR(__xludf.DUMMYFUNCTION("""COMPUTED_VALUE"""),422.9) -> 422.9 | BB16: =IFERROR(__xludf.DUMMYFUNCTION("""COMPUTED_VALUE"""),425.9) -> 425.9 | BC16: =IFERROR(__xludf.DUMMYFUNCTION("""COMPUTED_VALUE"""),8746243.0) -> 8746243 | BD16: =LN(BB16/BB15) -> -0.0098131629 | BQ16: Standard Deviation | BR16: =STDEV('Part A'!$H$7:$H$271)*(252)^0.5 -> 0.16999944 | BS16: =STDEV(T7:T271)*15.8745078664 -> 0.20830139 | BT16: =STDEV(AF8:AF271)*15.8745078664 -> 0.37354583 | BU16: =STDEV('Part A'!$AR$7:$AR$271)*15.8745078664 -> 0.43847136
B17: 45398 | C17: 6398.04 | D17: 6450.94 | E17: 6345.29 | F17: 6406.13 | G17: - | H17: =LN(F17/F16) -> 0.0020391891 | N17: =IFERROR(__xludf.DUMMYFUNCTION("""COMPUTED_VALUE"""),45398.64583333333) -> 45398.646 | O17: =IFERROR(__xludf.DUMMYFUNCTION("""COMPUTED_VALUE"""),1070.55) -> 1070.55 | P17: =IFERROR(__xludf.DUMMYFUNCTION("""COMPUTED_VALUE"""),1074.6) -> 1074.6 | Q17: =IFERROR(__xludf.DUMMYFUNCTION("""COMPUTED_VALUE"""),1062.7) -> 1062.7 | R17: =IFERROR(__xludf.DUMMYFUNCTION("""COMPUTED_VALUE"""),1067.05) -> 1067.05 | S17: =IFERROR(__xludf.DUMMYFUNCTION("""COMPUTED_VALUE"""),1.1278092E7) -> 11278092 | T17: =LN(R17/R16) -> -0.010534264 | Z17: =IFERROR(__xludf.DUMMYFUNCTION("""COMPUTED_VALUE"""),45398.64583333333) -> 45398.646 | AA17: =IFERROR(__xludf.DUMMYFUNCTION("""COMPUTED_VALUE"""),336.8) -> 336.8 | AB17: =IFERROR(__xludf.DUMMYFUNCTION("""COMPUTED_VALUE"""),339.15) -> 339.15 | AC17: =IFERROR(__xludf.DUMMYFUNCTION("""COMPUTED_VALUE"""),326.45) -> 326.45 | AD17: =IFERROR(__xludf.DUMMYFUNCTION("""COMPUTED_VALUE"""),332.5) -> 332.5 | AE17: =IFERROR(__xludf.DUMMYFUNCTION("""COMPUTED_VALUE"""),1.499568E7) -> 14995680 | AF17: =LN(AD17/AD16) -> -0.0061464851 | AL17: =IFERROR(__xludf.DUMMYFUNCTION("""COMPUTED_VALUE"""),45398.64583333333) -> 45398.646 | AM17: =IFERROR(__xludf.DUMMYFUNCTION("""COMPUTED_VALUE"""),3626.0) -> 3626 | AN17: =IFERROR(__xludf.DUMMYFUNCTION("""COMPUTED_VALUE"""),3738.95) -> 3738.95 | AO17: =IFERROR(__xludf.DUMMYFUNCTION("""COMPUTED_VALUE"""),3585.35) -> 3585.35 | AP17: =IFERROR(__xludf.DUMMYFUNCTION("""COMPUTED_VALUE"""),3722.15) -> 3722.15 | AQ17: =IFERROR(__xludf.DUMMYFUNCTION("""COMPUTED_VALUE"""),2939862.0) -> 2939862 | AR17: =LN(AP17/AP16) -> 0.025275443 | AX17: =IFERROR(__xludf.DUMMYFUNCTION("""COMPUTED_VALUE"""),45398.64583333333) -> 45398.646 | AY17: =IFERROR(__xludf.DUMMYFUNCTION("""COMPUTED_VALUE"""),423.25) -> 423.25 | AZ17: =IFERROR(__xludf.DUMMYFUNCTION("""COMPUTED_VALUE"""),427.0) -> 427 | BA17: =IFERROR(__xludf.DUMMYFUNCTION("""COMPUTED_VALUE"""),423.2) -> 423.2 | BB17: =IFERROR(__xludf.DUMMYFUNCTION("""COMPUTED_VALUE"""),425.9) -> 425.9 | BC17: =IFERROR(__xludf.DUMMYFUNCTION("""COMPUTED_VALUE"""),9973638.0) -> 9973638 | BD17: =LN(BB17/BB16) -> 0 | BQ17: PORTFOLIO | BR17: RETURN | BS17: VARIANCE | BT17: STANDARD DEVIATION | BU17: STANDARD DEVIATION(%) | BV17: SHARPE RATIO
B18: 45400 | C18: 6342.86 | D18: 6426.98 | E18: 6342.86 | F18: 6388.2 | G18: - | H18: =LN(F18/F17) -> -0.0028028059 | N18: =IFERROR(__xludf.DUMMYFUNCTION("""COMPUTED_VALUE"""),45400.64583333333) -> 45400.646 | O18: =IFERROR(__xludf.DUMMYFUNCTION("""COMPUTED_VALUE"""),1074.0) -> 1074 | P18: =IFERROR(__xludf.DUMMYFUNCTION("""COMPUTED_VALUE"""),1078.05) -> 1078.05 | Q18: =IFERROR(__xludf.DUMMYFUNCTION("""COMPUTED_VALUE"""),1050.45) -> 1050.45 | R18: =IFERROR(__xludf.DUMMYFUNCTION("""COMPUTED_VALUE"""),1055.45) -> 1055.45 | S18: =IFERROR(__xludf.DUMMYFUNCTION("""COMPUTED_VALUE"""),1.6564216E7) -> 16564216 | T18: =LN(R18/R17) -> -0.010930615 | Z18: =IFERROR(__xludf.DUMMYFUNCTION("""COMPUTED_VALUE"""),45400.64583333333) -> 45400.646 | AA18: =IFERROR(__xludf.DUMMYFUNCTION("""COMPUTED_VALUE"""),335.5) -> 335.5 | AB18: =IFERROR(__xludf.DUMMYFUNCTION("""COMPUTED_VALUE"""),353.85) -> 353.85 | AC18: =IFERROR(__xludf.DUMMYFUNCTION("""COMPUTED_VALUE"""),335.0) -> 335 | AD18: =IFERROR(__xludf.DUMMYFUNCTION("""COMPUTED_VALUE"""),344.4) -> 344.4 | AE18: =IFERROR(__xludf.DUMMYFUNCTION("""COMPUTED_VALUE"""),4.0001173E7) -> 40001173 | AF18: =LN(AD18/AD17) -> 0.035163912 | AL18: =IFERROR(__xludf.DUMMYFUNCTION("""COMPUTED_VALUE"""),45400.64583333333) -> 45400.646 | AM18: =IFERROR(__xludf.DUMMYFUNCTION("""COMPUTED_VALUE"""),3744.0) -> 3744 | AN18: =IFERROR(__xludf.DUMMYFUNCTION("""COMPUTED_VALUE"""),3768.0) -> 3768 | AO18: =IFERROR(__xludf.DUMMYFUNCTION("""COMPUTED_VALUE"""),3652.7) -> 3652.7 | AP18: =IFERROR(__xludf.DUMMYFUNCTION("""COMPUTED_VALUE"""),3677.15) -> 3677.15 | AQ18: =IFERROR(__xludf.DUMMYFUNCTION("""COMPUTED_VALUE"""),2294396.0) -> 2294396 | AR18: =LN(AP18/AP17) -> -0.012163463 | AX18: =IFERROR(__xludf.DUMMYFUNCTION("""COMPUTED_VALUE"""),45400.64583333333) -> 45400.646 | AY18: =IFERROR(__xludf.DUMMYFUNCTION("""COMPUTED_VALUE"""),426.0) -> 426 | AZ18: =IFERROR(__xludf.DUMMYFUNCTION("""COMPUTED_VALUE"""),426.9) -> 426.9 | BA18: =IFERROR(__xludf.DUMMYFUNCTION("""COMPUTED_VALUE"""),417.65) -> 417.65 | BB18: =IFERROR(__xludf.DUMMYFUNCTION("""COMPUTED_VALUE"""),418.85) -> 418.85 | BC18: =IFERROR(__xludf.DUMMYFUNCTION("""COMPUTED_VALUE"""),2.1312388E7) -> 21312388 | BD18: =LN(BB18/BB17) -> -0.016691716 | BQ18: VALUES | BR18: {=MMULT($BR$14:$BU$14, TRANSPOSE($BR$15:$BU$15))} -> 0.32848285 | BS18: {=MMULT($BR$14:$BU$14, MMULT('Part A'!$BL$6:$BO$9, TRANSPOSE($BR$14:$BU$14)))} -> 0.044223365 | BT18: {=SQRT(MMULT($BR$14:$BU$14, MMULT('Part A'!$BL$6:$BO$9, TRANSPOSE($BR$14:$BU$14))))} -> 0.21029352 | BU18: {=SQRT(MMULT($BR$14:$BU$14, MMULT('Part A'!$BL$6:$BO$9, TRANSPOSE($BR$14:$BU$14))))} -> 0.21029352 | BV18: =($BR$18-'Part A'!$BI$7)/($BU$18) -> 1.2833626
B19: 45401 | C19: 6389.53 | D19: 6500.33 | E19: 6364.78 | F19: 6408.75 | G19: - | H19: =LN(F19/F18) -> 0.0032117055 | N19: =IFERROR(__xludf.DUMMYFUNCTION("""COMPUTED_VALUE"""),45401.64583333333) -> 45401.646 | O19: =IFERROR(__xludf.DUMMYFUNCTION("""COMPUTED_VALUE"""),1052.95) -> 1052.95 | P19: =IFERROR(__xludf.DUMMYFUNCTION("""COMPUTED_VALUE"""),1072.0) -> 1072 | Q19: =IFERROR(__xludf.DUMMYFUNCTION("""COMPUTED_VALUE"""),1048.1) -> 1048.1 | R19: =IFERROR(__xludf.DUMMYFUNCTION("""COMPUTED_VALUE"""),1067.25) -> 1067.25 | S19: =IFERROR(__xludf.DUMMYFUNCTION("""COMPUTED_VALUE"""),1.1284433E7) -> 11284433 | T19: =LN(R19/R18) -> 0.01111803 | Z19: =IFERROR(__xludf.DUMMYFUNCTION("""COMPUTED_VALUE"""),45401.64583333333) -> 45401.646 | AA19: =IFERROR(__xludf.DUMMYFUNCTION("""COMPUTED_VALUE"""),342.05) -> 342.05 | AB19: =IFERROR(__xludf.DUMMYFUNCTION("""COMPUTED_VALUE"""),359.5) -> 359.5 | AC19: =IFERROR(__xludf.DUMMYFUNCTION("""COMPUTED_VALUE"""),336.85) -> 336.85 | AD19: =IFERROR(__xludf.DUMMYFUNCTION("""COMPUTED_VALUE"""),351.4) -> 351.4 | AE19: =IFERROR(__xludf.DUMMYFUNCTION("""COMPUTED_VALUE"""),4.0376246E7) -> 40376246 | AF19: =LN(AD19/AD18) -> 0.020121403 | AL19: =IFERROR(__xludf.DUMMYFUNCTION("""COMPUTED_VALUE"""),45401.64583333333) -> 45401.646 | AM19: =IFERROR(__xludf.DUMMYFUNCTION("""COMPUTED_VALUE"""),3660.0) -> 3660 | AN19: =IFERROR(__xludf.DUMMYFUNCTION("""COMPUTED_VALUE"""),3761.15) -> 3761.15 | AO19: =IFERROR(__xludf.DUMMYFUNCTION("""COMPUTED_VALUE"""),3621.0) -> 3621 | AP19: =IFERROR(__xludf.DUMMYFUNCTION("""COMPUTED_VALUE"""),3751.3) -> 3751.3 | AQ19: =IFERROR(__xludf.DUMMYFUNCTION("""COMPUTED_VALUE"""),2256325.0) -> 2256325 | AR19: =LN(AP19/AP18) -> 0.019964451 | AX19: =IFERROR(__xludf.DUMMYFUNCTION("""COMPUTED_VALUE"""),45401.64583333333) -> 45401.646 | AY19: =IFERROR(__xludf.DUMMYFUNCTION("""COMPUTED_VALUE"""),418.0) -> 418 | AZ19: =IFERROR(__xludf.DUMMYFUNCTION("""COMPUTED_VALUE"""),426.25) -> 426.25 | BA19: =IFERROR(__xludf.DUMMYFUNCTION("""COMPUTED_VALUE"""),416.0) -> 416 | BB19: =IFERROR(__xludf.DUMMYFUNCTION("""COMPUTED_VALUE"""),424.75) -> 424.75 | BC19: =IFERROR(__xludf.DUMMYFUNCTION("""COMPUTED_VALUE"""),1.6582634E7) -> 16582634 | BD19: =LN(BB19/BB18) -> 0.0139879
B20: 45404 | C20: 6402.05 | D20: 6403.56 | E20: 6232.12 | F20: 6234.84 | G20: - | H20: =LN(F20/F19) -> -0.027511327 | N20: =IFERROR(__xludf.DUMMYFUNCTION("""COMPUTED_VALUE"""),45404.64583333333) -> 45404.646 | O20: =IFERROR(__xludf.DUMMYFUNCTION("""COMPUTED_VALUE"""),1078.8) -> 1078.8 | P20: =IFERROR(__xludf.DUMMYFUNCTION("""COMPUTED_VALUE"""),1088.7) -> 1088.7 | Q20: =IFERROR(__xludf.DUMMYFUNCTION("""COMPUTED_VALUE"""),1070.35) -> 1070.35 | R20: =IFERROR(__xludf.DUMMYFUNCTION("""COMPUTED_VALUE"""),1086.65) -> 1086.65 | S20: =IFERROR(__xludf.DUMMYFUNCTION("""COMPUTED_VALUE"""),1.0346714E7) -> 10346714 | T20: =LN(R20/R19) -> 0.018014323 | Z20: =IFERROR(__xludf.DUMMYFUNCTION("""COMPUTED_VALUE"""),45404.64583333333) -> 45404.646 | AA20: =IFERROR(__xludf.DUMMYFUNCTION("""COMPUTED_VALUE"""),352.0) -> 352 | AB20: =IFERROR(__xludf.DUMMYFUNCTION("""COMPUTED_VALUE"""),355.25) -> 355.25 | AC20: =IFERROR(__xludf.DUMMYFUNCTION("""COMPUTED_VALUE"""),341.65) -> 341.65 | AD20: =IFERROR(__xludf.DUMMYFUNCTION("""COMPUTED_VALUE"""),349.8) -> 349.8 | AE20: =IFERROR(__xludf.DUMMYFUNCTION("""COMPUTED_VALUE"""),1.8832015E7) -> 18832015 | AF20: =LN(AD20/AD19) -> -0.0045636132 | AL20: =IFERROR(__xludf.DUMMYFUNCTION("""COMPUTED_VALUE"""),45404.64583333333) -> 45404.646 | AM20: =IFERROR(__xludf.DUMMYFUNCTION("""COMPUTED_VALUE"""),3800.0) -> 3800 | AN20: =IFERROR(__xludf.DUMMYFUNCTION("""COMPUTED_VALUE"""),3810.0) -> 3810 | AO20: =IFERROR(__xludf.DUMMYFUNCTION("""COMPUTED_VALUE"""),3732.6) -> 3732.6 | AP20: =IFERROR(__xludf.DUMMYFUNCTION("""COMPUTED_VALUE"""),3785.5) -> 3785.5 | AQ20: =IFERROR(__xludf.DUMMYFUNCTION("""COMPUTED_VALUE"""),1337755.0) -> 1337755 | AR20: =LN(AP20/AP19) -> 0.009075532 | AX20: =IFERROR(__xludf.DUMMYFUNCTION("""COMPUTED_VALUE"""),45404.64583333333) -> 45404.646 | AY20: =IFERROR(__xludf.DUMMYFUNCTION("""COMPUTED_VALUE"""),427.0) -> 427 | AZ20: =IFERROR(__xludf.DUMMYFUNCTION("""COMPUTED_VALUE"""),427.6) -> 427.6 | BA20: =IFERROR(__xludf.DUMMYFUNCTION("""COMPUTED_VALUE"""),423.35) -> 423.35 | BB20: =IFERROR(__xludf.DUMMYFUNCTION("""COMPUTED_VALUE"""),425.3) -> 425.3 | BC20: =IFERROR(__xludf.DUMMYFUNCTION("""COMPUTED_VALUE"""),7112139.0) -> 7112139 | BD20: =LN(BB20/BB19) -> 0.0012940417
B21: 45405 | C21: 6237.19 | D21: 6258.85 | E21: 6139.58 | F21: 6215.31 | G21: - | H21: =LN(F21/F20) -> -0.0031373142 | N21: =IFERROR(__xludf.DUMMYFUNCTION("""COMPUTED_VALUE"""),45405.64583333333) -> 45405.646 | O21: =IFERROR(__xludf.DUMMYFUNCTION("""COMPUTED_VALUE"""),1100.0) -> 1100 | P21: =IFERROR(__xludf.DUMMYFUNCTION("""COMPUTED_VALUE"""),1100.0) -> 1100 | Q21: =IFERROR(__xludf.DUMMYFUNCTION("""COMPUTED_VALUE"""),1082.7) -> 1082.7 | R21: =IFERROR(__xludf.DUMMYFUNCTION("""COMPUTED_VALUE"""),1090.25) -> 1090.25 | S21: =IFERROR(__xludf.DUMMYFUNCTION("""COMPUTED_VALUE"""),9848215.0) -> 9848215 | T21: =LN(R21/R20) -> 0.0033074586 | Z21: =IFERROR(__xludf.DUMMYFUNCTION("""COMPUTED_VALUE"""),45405.64583333333) -> 45405.646 | AA21: =IFERROR(__xludf.DUMMYFUNCTION("""COMPUTED_VALUE"""),359.85) -> 359.85 | AB21: =IFERROR(__xludf.DUMMYFUNCTION("""COMPUTED_VALUE"""),366.55) -> 366.55 | AC21: =IFERROR(__xludf.DUMMYFUNCTION("""COMPUTED_VALUE"""),356.85) -> 356.85 | AD21: =IFERROR(__xludf.DUMMYFUNCTION("""COMPUTED_VALUE"""),359.5) -> 359.5 | AE21: =IFERROR(__xludf.DUMMYFUNCTION("""COMPUTED_VALUE"""),2.7662734E7) -> 27662734 | AF21: =LN(AD21/AD20) -> 0.027352615 | AL21: =IFERROR(__xludf.DUMMYFUNCTION("""COMPUTED_VALUE"""),45405.64583333333) -> 45405.646 | AM21: =IFERROR(__xludf.DUMMYFUNCTION("""COMPUTED_VALUE"""),3800.0) -> 3800 | AN21: =IFERROR(__xludf.DUMMYFUNCTION("""COMPUTED_VALUE"""),3831.85) -> 3831.85 | AO21: =IFERROR(__xludf.DUMMYFUNCTION("""COMPUTED_VALUE"""),3783.05) -> 3783.05 | AP21: =IFERROR(__xludf.DUMMYFUNCTION("""COMPUTED_VALUE"""),3795.7) -> 3795.7 | AQ21: =IFERROR(__xludf.DUMMYFUNCTION("""COMPUTED_VALUE"""),1321429.0) -> 1321429 | AR21: =LN(AP21/AP20) -> 0.0026908685 | AX21: =IFERROR(__xludf.DUMMYFUNCTION("""COMPUTED_VALUE"""),45405.64583333333) -> 45405.646 | AY21: =IFERROR(__xludf.DUMMYFUNCTION("""COMPUTED_VALUE"""),425.3) -> 425.3 | AZ21: =IFERROR(__xludf.DUMMYFUNCTION("""COMPUTED_VALUE"""),430.5) -> 430.5 | BA21: =IFERROR(__xludf.DUMMYFUNCTION("""COMPUTED_VALUE"""),425.1) -> 425.1 | BB21: =IFERROR(__xludf.DUMMYFUNCTION("""COMPUTED_VALUE"""),429.2) -> 429.2 | BC21: =IFERROR(__xludf.DUMMYFUNCTION("""COMPUTED_VALUE"""),1.2021404E7) -> 12021404 | BD21: =LN(BB21/BB20) -> 0.0091282085 | BQ21: OPTIMAL WEIGHT
